fn create context oci-context --provider oracle
fn update context oci-context oracle.region us-ashburn-1
fn update context oci-context oracle.compartment-id <COMPARTMENT_OCID>
fn use context oci-context

[opc@oci-admin-01 ~]$ fn update context oci-context oracle.region us-ashburn-1

Fn: open /home/opc/.fn/contexts/.yaml: no such file or directory

See 'fn <command> --help' for more information. Client version: 0.6.43
[opc@oci-admin-01 ~]$

fn update context oci-context api-url https://functions.us-ashburn-1.oci.oraclecloud.com

fn create context oci-context --provider oracle \
  --api-url https://functions.us-ashburn-1.oci.oraclecloud.com

fn create context oci-context \
  --provider oracle \
  --api-url https://functions.us-ashburn-1.oci.oraclecloud.com \
  --oracle.region us-ashburn-1 \
  --oracle.compartment-id ocid1.compartment.oc1..aaaaaaaal3ny7cdvz3ovgcq43x7vqexyyy4s2fozfo4zhked7xsyzbhsx7bq

Option 2 â€” Create + Edit YAML
bash
Kopieren
Bearbeiten
fn create context oci-context \
  --provider oracle \
  --api-url https://functions.us-ashburn-1.oci.oraclecloud.com

nano ~/.fn/contexts/oci-context.yaml
Then manually add:

yaml
Kopieren
Bearbeiten
oracle.region: us-ashburn-1
oracle.compartment-id: <COMPARTMENT_OCID>

fn config function cloud-guard-processing-app cloud_guard_processor BUCKET_NAME cloud-guard-findings-bucket

Successfully created function: cloud_guard_processor with iad.ocir.io/acscloudengineering/cloud-guard-functions/cloud_guard_processor:0.0.4
[opc@oci-admin-01 cloud_guard_processor]$ fn invoke cloud-guard-processing-app cloud_guard_processor
Error invoking function. status: 502 message: function failed

oci logging search-logs \
  --search-query "search \"FunctionsExecution\" where appName = 'cloud-guard-processing-app'" \
  --time-start 10m


echo "_L>Dr8F-m8_]YrN>TaF8" | docker login iad.ocir.io  \
--username "acscloudengineering/gregory.ohwerhi@oracle.com" \
--password-stdin

tZ[-RP#I#TOieRz79SmC

echo "tZ[-RP#I#TOieRz79SmC" | docker login iad.ocir.io  \
--username "acscloudengineering/gregory.ohwerhi@oracle.com" \
--password-stdin

echo "tZ[-RP#I#TOieRz79SmC" | docker login iad.ocir.io  --username "acscloudengineering/oracleidentitycloudservice/gregory.ohwerhi@oracle.com" --password-stdin

[opc@oci-admin-01 cloud_guard_processor]$ echo '{"finding":"test"}' | fn invoke cloud-guard-processing-app cloud_guard_processor
Error: {'target_service': 'object_storage', 'status': 404, 'code': 'BucketNotFound', 'opc-request-id': 'iad-1:2Kats6lJBJf6Wj0gTxrwpo-dXoP0epgmfsbFx-xilfZaUskGPuks689lbQudxNs8', 'message': "Either the bucket named 'cloud-guard-findings-bucket' does not exist in the namespace 'acscloudengineering' or you are not authorized to access it", 'operation_name': 'put_object', 'timestamp': '2025-08-18T09:15:41.614311+00:00', 'client_version': 'Oracle-PythonSDK/2.158.0', 'request_endpoint': 'PUT https://objectstorage.us-ashburn-1.oraclecloud.com/n/acscloudengineering/b/cloud-guard-findings-bucket/o/2025-08-18T09-15-41Z_unknown_finding.json', 'logging_tips': 'To get more info on the failing request, refer to https://docs.oracle.com/en-us/iaas/tools/python/latest/logging.html for ways to log the request/response details.', 'troubleshooting_tips': "See https://docs.oracle.com/iaas/Content/API/References/apierrors.htm#apierrors_404__404_bucketnotfound for more information about resolving this error. Also see https://docs.oracle.com/iaas/api/#/en/objectstorage/20160918/Object/PutObject for details on this operation's requirements. If you are unable to resolve this object_storage issue, please contact Oracle support and provide them this full error message."}



echo '{"id":"finding-test","severity":"HIGH"}' | fn invoke cloud-guard-processing-app cloud_guard_processor

[opc@oci-admin-01 cloud_guard_processor]$ echo '{"id":"finding-test"}' |DEBUG=1 fn invoke cloud-guard-processing-app cloud_guard_processor
POST /20181201/functions/ocid1.fnfunc.oc1.iad.aaaaaaaaanek6owb3wzp6yiljtyp3fnmtgj6ywghigm524hpxb6s3fyjqvhq/actions/invoke HTTP/1.1
Host: ob3xlmlev3a.us-ashburn-1.functions.oci.oraclecloud.com
User-Agent: Go-http-client/1.1
Content-Length: 22
Content-Type: text/plain
Accept-Encoding: gzip

{"id":"finding-test"}

HTTP/1.1 502 Bad Gateway
Content-Length: 68
Content-Type: application/json
Date: Wed, 27 Aug 2025 07:25:55 GMT
Fn-Call-Id: 01K3N6PGVN1BT1358ZJ0002QEJ
Opc-Request-Id: /01K3N6PGSM0000000000005CCV/01K3N6PGSM0000000000005CCW

{"code":"FunctionInvokeExecutionFailed","message":"function failed"}
Error invoking function. status: 502 message: function failed

"01K3NA5BWY1BT155GZJ0001BWH - fn - ERROR - inconsistent use of tabs and spaces in indentation (func.py, line 25):  File \"/python/fdk/runner.py\", line 74, in handle_request\\n    response_data = await with_deadline(ctx, handler_code, body)\\n  File \"/python/fdk/runner.py\", line 54, in with_deadline\\n    raise ex\\n  File \"/python/fdk/runner.py\", line 47, in with_deadline\\n    handle_func = handler_code.handler()\\n  File \"/python/fdk/customer_code.py\", line 94, in handler\\n    mod = self._delayed_module_class.get_module()\\n  File \"/python/fdk/customer_code.py\", line 58, in get_module\\n    self._func_module = SourceFileLoader(fname, self._mod_path)\\\\n  File \"<frozen importlib._bootstrap_external>\", line 529, in _check_name_wrapper\\n  File \"<frozen importlib._bootstrap_external>\", line 1030, in load_module\\n  File \"<frozen importlib._bootstrap_external>\", line 854, in load_module\\n  File \"<frozen importlib._bootstrap>\", line 274, in _load_module_shim\\n  File \"<frozen importlib._bootstrap>\", line 711, in _load\\n  File \"<frozen importlib._bootstrap>\", line 680, in _load_unlocked\\n  File \"<frozen importlib._bootstrap_external>\", line 846, in exec_module\\n  File \"<frozen importlib._bootstrap_external>\", line 983, in get_code\\n  File \"<frozen importlib._bootstrap_external>\", line 913, in source_to_code\\n  File \"<frozen importlib._bootstrap>\", line 228, in _call_with_frames_removed\\n"

{
  "datetime": 1756283240094,
  "logContent": {
    "data": {
      "applicationId": "ocid1.fnapp.oc1.iad.aaaaaaaarkxww5zfglqxdkhdttctsums7rzdkbzxxkm67chbqob3xlmlev3a",
      "containerId": "01K3NA6EBF00000000000000SH",
      "functionId": "ocid1.fnfunc.oc1.iad.aaaaaaaaanek6owb3wzp6yiljtyp3fnmtgj6ywghigm524hpxb6s3fyjqvhq",
      "message": "01K3NA5BWY1BT155GZJ0001BWH - fn - ERROR - inconsistent use of tabs and spaces in indentation (func.py, line 25):  File \"/python/fdk/runner.py\", line 74, in handle_request\\n    response_data = await with_deadline(ctx, handler_code, body)\\n  File \"/python/fdk/runner.py\", line 54, in with_deadline\\n    raise ex\\n  File \"/python/fdk/runner.py\", line 47, in with_deadline\\n    handle_func = handler_code.handler()\\n  File \"/python/fdk/customer_code.py\", line 94, in handler\\n    mod = self._delayed_module_class.get_module()\\n  File \"/python/fdk/customer_code.py\", line 58, in get_module\\n    self._func_module = SourceFileLoader(fname, self._mod_path)\\\\n  File \"<frozen importlib._bootstrap_external>\", line 529, in _check_name_wrapper\\n  File \"<frozen importlib._bootstrap_external>\", line 1030, in load_module\\n  File \"<frozen importlib._bootstrap_external>\", line 854, in load_module\\n  File \"<frozen importlib._bootstrap>\", line 274, in _load_module_shim\\n  File \"<frozen importlib._bootstrap>\", line 711, in _load\\n  File \"<frozen importlib._bootstrap>\", line 680, in _load_unlocked\\n  File \"<frozen importlib._bootstrap_external>\", line 846, in exec_module\\n  File \"<frozen importlib._bootstrap_external>\", line 983, in get_code\\n  File \"<frozen importlib._bootstrap_external>\", line 913, in source_to_code\\n  File \"<frozen importlib._bootstrap>\", line 228, in _call_with_frames_removed\\n",
      "opcRequestId": "/01K3NA5BV600000000000033V2/01K3NA5BV600000000000033V3",
      "requestId": "/01K3NA5BV600000000000033V2/01K3NA5BV600000000000033V3",
      "src": "STDERR"
    },
    "id": "4a08244b-c97c-4ea2-a85a-8acec8139862",
    "oracle": {
      "compartmentid": "ocid1.compartment.oc1..aaaaaaaal3ny7cdvz3ovgcq43x7vqexyyy4s2fozfo4zhked7xsyzbhsx7bq",
      "ingestedtime": "2025-08-27T08:27:24.869Z",
      "loggroupid": "ocid1.loggroup.oc1.iad.amaaaaaa3vux2giawc2yzxo5rqacetrng47qkupddp4gt6ccp5mbvocfrhha",
      "logid": "ocid1.log.oc1.iad.amaaaaaa3vux2gia6qcaipq52e2klhlemmdwadhxffomcgdfcxwt3whchknq",
      "tenantid": "ocid1.tenancy.oc1..aaaaaaaaabc4esylkbw3jkbquuluuq4iftuuwnfc2yg2fguo4s7j43exv6pq"
    },
    "source": "cloud-guard-processing-app",
    "specversion": "1.0",
    "subject": "cloud_guard_processor",
    "time": "2025-08-27T08:27:20.094Z",
    "type": "com.oraclecloud.functions.application.functioninvoke"
  },
  "regionId": "us-ashburn-1"
}

"Served function invocation request in 53.021 seconds with error code 502 - FunctionInvokeExecutionFailed (502): function failed "
{
  "datetime": 1756283240122,
  "logContent": {
    "data": {
      "applicationId": "ocid1.fnapp.oc1.iad.aaaaaaaarkxww5zfglqxdkhdttctsums7rzdkbzxxkm67chbqob3xlmlev3a",
      "containerId": "n/a",
      "functionId": "ocid1.fnfunc.oc1.iad.aaaaaaaaanek6owb3wzp6yiljtyp3fnmtgj6ywghigm524hpxb6s3fyjqvhq",
      "message": "Served function invocation request in 53.021 seconds with error code 502 - FunctionInvokeExecutionFailed (502): function failed ",
      "opcRequestId": "/01K3NA5BV600000000000033V2/01K3NA5BV600000000000033V3",
      "requestId": "/01K3NA5BV600000000000033V2/01K3NA5BV600000000000033V3",
      "src": "stdout"
    },
    "id": "e2058f29-591b-4b1e-bd28-c0ca46676abf",
    "oracle": {
      "compartmentid": "ocid1.compartment.oc1..aaaaaaaal3ny7cdvz3ovgcq43x7vqexyyy4s2fozfo4zhked7xsyzbhsx7bq",
      "ingestedtime": "2025-08-27T08:27:21.400Z",
      "loggroupid": "ocid1.loggroup.oc1.iad.amaaaaaa3vux2giawc2yzxo5rqacetrng47qkupddp4gt6ccp5mbvocfrhha",
      "logid": "ocid1.log.oc1.iad.amaaaaaa3vux2gia6qcaipq52e2klhlemmdwadhxffomcgdfcxwt3whchknq",
      "tenantid": "ocid1.tenancy.oc1..aaaaaaaaabc4esylkbw3jkbquuluuq4iftuuwnfc2yg2fguo4s7j43exv6pq"
    },
    "source": "cloud-guard-processing-app",
    "specversion": "1.0",
    "subject": "cloud_guard_processor",
    "time": "2025-08-27T08:27:20.122Z",
    "type": "com.oraclecloud.functions.application.functioninvoke"
  },
  "regionId": "us-ashburn-1"
}

Error: {'target_service': 'object_storage', 'status': 404, 'code': 'NamespaceNotFound', 'opc-request-id': 'iad-1:WjXfGAtgi6BYLOhw1XWLHZNJfRZ_BK1F3pw_FTtLU7IUVHQHwyVmfcx5H3jAIG_8', 'message': 'You do not have authorization to perform this request, or the requested resource could not be found.', 'operation_name': 'list_buckets', 'timestamp': '2025-08-27T08:40:01.663956+00:00', 'client_version': 'Oracle-PythonSDK/2.158.0', 'request_endpoint': 'GET https://objectstorage.us-ashburn-1.oraclecloud.com/n/acscloudengineering/b', 'logging_tips': 'To get more info on the failing request, refer to https://docs.oracle.com/en-us/iaas/tools/python/latest/logging.html for ways to log the request/response details.', 'troubleshooting_tips': "See https://docs.oracle.com/iaas/Content/API/References/apierrors.htm#apierrors_404__404_namespacenotfound for more information about resolving this error. Also see https://docs.oracle.com/iaas/api/#/en/objectstorage/20160918/Bucket/ListBuckets for details on this operation's requirements. If you are unable to resolve this object_storage issue, please contact Oracle support and provide them this full error message."}
Error: {'target_service': 'object_storage', 'status': 404, 'code': 'NamespaceNotFound', 'opc-request-id': 'iad-1:WjXfGAtgi6BYLOhw1XWLHZNJfRZ_BK1F3pw_FTtLU7IUVHQHwyVmfcx5H3jAIG_8', 'message': 'You do not have authorization to perform this request, or the requested resource could not be found.', 'operation_name': 'list_buckets', 'timestamp': '2025-08-27T08:40:01.663956+00:00', 'client_version': 'Oracle-PythonSDK/2.158.0', 'request_endpoint': 'GET https://objectstorage.us-ashburn-1.oraclecloud.com/n/acscloudengineering/b', 'logging_tips': 'To get more info on the failing request, refer to https://docs.oracle.com/en-us/iaas/tools/python/latest/logging.html for ways to log the request/response details.', 'troubleshooting_tips': "See https://docs.oracle.com/iaas/Content/API/References/apierrors.htm#apierrors_404__404_namespacenotfound for more information about resolving this error. Also see https://docs.oracle.com/iaas/api/#/en/objectstorage/20160918/Bucket/ListBuckets for details on this operation's requirements. If you are unable to resolve this object_storage issue, please contact Oracle support and provide them this full error message."}


"01K3NKK3M41BT1460ZJ000JMEN - root - ERROR - Error processing event: {'target_service': 'object_storage', 'status': 404, 'code': 'NamespaceNotFound', 'opc-request-id': 'iad-1:FscVmZO-N9PJ2SOHRwgneou6_a8hq82zFbaQp_WC26UDw6gsqJKQzqg_P8kPyi6J', 'message': 'You do not have authorization to perform this request, or the requested resource could not be found.', 'operation_name': 'list_buckets', 'timestamp': '2025-08-27T11:11:53.631865+00:00', 'client_version': 'Oracle-PythonSDK/2.158.0', 'request_endpoint': 'GET https://objectstorage.us-ashburn-1.oraclecloud.com/n/acscloudengineering/b', 'logging_tips': 'To get more info on the failing request, refer to https://docs.oracle.com/en-us/iaas/tools/python/latest/logging.html for ways to log the request/response details.', 'troubleshooting_tips': \"See https://docs.oracle.com/iaas/Content/API/References/apierrors.htm#apierrors_404__404_namespacenotfound for more information about resolving this error. Also see https://docs.oracle.com/iaas/api/#/en/objectstorage/20160918/Bucket/ListBuckets for details on this operation's requirements. If you are unable to resolve this object_storage issue, please contact Oracle support and provide them this full error message.\"}"
"01K3NKK3M41BT1460ZJ000JMEN - oci.circuit_breaker.circuit_breaker - DEBUG - status code:404 not in failure_statuses_and_codes:{409: ['IncorrectState'], 429: [], 500: [], 502: [], 503: [], 504: []}"
"01K3NKK3M41BT1460ZJ000JMEN - oci.circuit_breaker.circuit_breaker - DEBUG - Is transient error status code:404 error code:NamespaceNotFound"
"01K3NKK3M41BT1460ZJ000JMEN - oci._vendor.urllib3.connectionpool - DEBUG - https://objectstorage.us-ashburn-1.oraclecloud.com:443 \"GET /n/acscloudengineering/b?compartmentId=ocid1.compartment.oc1..aaaaaaaal3ny7cdvz3ovgcq43x7vqexyyy4s2fozfo4zhked7xsyzbhsx7bq HTTP/1.1\" 404 141"
"01K3NKK3M41BT1460ZJ000JMEN - root - INFO - Resolved Namespace: acscloudengineering"
"01K3NKK3M41BT1460ZJ000JMEN - oci._vendor.urllib3.connectionpool - DEBUG - https://objectstorage.us-ashburn-1.oraclecloud.com:443 \"GET /n HTTP/1.1\" 200 21"
"01K3NKK3M41BT1460ZJ000JMEN - oci._vendor.urllib3.connectionpool - DEBUG - Starting new HTTPS connection (1): objectstorage.us-ashburn-1.oraclecloud.com:443"
"01K3NKK3M41BT1460ZJ000JMEN - root - INFO - Signer: <oci.auth.signers.ephemeral_resource_principals_signer.EphemeralResourcePrincipalSigner object at 0x7f94e6f09c40>"
"01K3NKK3M41BT1460ZJ000JMEN - root - INFO - Event received: {'id': 'finding-test'}"


Traceback (most recent call last):
  File "/home/opc/python/lib/python3.7/site-packages/oci/_vendor/urllib3/connection.py", line 180, in _new_conn
    (self._dns_host, self.port), self.timeout, **extra_kw
  File "/home/opc/python/lib/python3.7/site-packages/oci/_vendor/urllib3/util/connection.py", line 77, in create_connection
    for res in socket.getaddrinfo(host, port, family, socket.SOCK_STREAM):
  File "/home/opc/python/lib/python3.7/socket.py", line 748, in getaddrinfo
    for res in _socket.getaddrinfo(host, port, family, type, proto, flags):
socket.gaierror: [Errno -2] Name or service not known

During handling of the above exception, another exception occurred:

Traceback (most recent call last):
  File "/home/opc/python/lib/python3.7/site-packages/oci/_vendor/urllib3/connectionpool.py", line 728, in urlopen
    chunked=chunked,
  File "/home/opc/python/lib/python3.7/site-packages/oci/_vendor/urllib3/connectionpool.py", line 409, in _make_request
    self._validate_conn(conn)
  File "/home/opc/python/lib/python3.7/site-packages/oci/_vendor/urllib3/connectionpool.py", line 1066, in _validate_conn
    conn.connect()
  File "/home/opc/python/lib/python3.7/site-packages/oci/_vendor/urllib3/connection.py", line 368, in connect
    self.sock = conn = self._new_conn()
  File "/home/opc/python/lib/python3.7/site-packages/oci/_vendor/urllib3/connection.py", line 192, in _new_conn
    self, "Failed to establish a new connection: %s" % e
oci._vendor.urllib3.exceptions.NewConnectionError: <oci.base_client.OCIConnection object at 0x7f4734370d68>: Failed to establish a new connection: [Errno -2] Name or service not known

During handling of the above exception, another exception occurred:

Traceback (most recent call last):
  File "/home/opc/python/lib/python3.7/site-packages/oci/_vendor/requests/adapters.py", line 458, in send
    enforce_content_length=True
  File "/home/opc/python/lib/python3.7/site-packages/oci/_vendor/urllib3/connectionpool.py", line 808, in urlopen
    method, url, error=e, _pool=self, _stacktrace=sys.exc_info()[2]
  File "/home/opc/python/lib/python3.7/site-packages/oci/_vendor/urllib3/util/retry.py", line 599, in increment
    raise MaxRetryError(_pool, url, error or ResponseError(cause))
oci._vendor.urllib3.exceptions.MaxRetryError: OCIConnectionPool(host='anomalydetection.aiservice.us-ashburn-1.oci.oraclecloud.com', port=443): Max retries exceeded with url: /20210101/dataAssets?compartmentId=ocid1.compartment.oc1..aaaaaaaaykn3hgoydak7wfeqplsd7vuqgsf2lhiojtcze4g3ojoowisxqcfq (Caused by NewConnectionError('<oci.base_client.OCIConnection object at 0x7f4734370d68>: Failed to establish a new connection: [Errno -2] Name or service not known'))

During handling of the above exception, another exception occurred:

Traceback (most recent call last):
  File "/home/opc/python/lib/python3.7/site-packages/oci/base_client.py", line 679, in request
    timeout=self.timeout)
  File "/home/opc/python/lib/python3.7/site-packages/oci/_vendor/requests/sessions.py", line 536, in request
    resp = self.send(prep, **send_kwargs)
  File "/home/opc/python/lib/python3.7/site-packages/oci/_vendor/requests/sessions.py", line 652, in send
    r = adapter.send(request, **kwargs)
  File "/home/opc/python/lib/python3.7/site-packages/oci/_vendor/requests/adapters.py", line 527, in send
    raise ConnectionError(e, request=request)
oci._vendor.requests.exceptions.ConnectionError: (MaxRetryError("OCIConnectionPool(host='anomalydetection.aiservice.us-ashburn-1.oci.oraclecloud.com', port=443): Max retries exceeded with url: /20210101/dataAssets?compartmentId=ocid1.compartment.oc1..aaaaaaaaykn3hgoydak7wfeqplsd7vuqgsf2lhiojtcze4g3ojoowisxqcfq (Caused by NewConnectionError('<oci.base_client.OCIConnection object at 0x7f4734370d68>: Failed to establish a new connection: [Errno -2] Name or service not known'))"), 'Request Endpoint: GET https://anomalydetection.aiservice.us-ashburn-1.oci.oraclecloud.com/20210101/dataAssets See https://docs.oracle.com/en-us/iaas/Content/API/Concepts/sdk_troubleshooting.htm for help troubleshooting this error, or contact support and provide this full error message.')

During handling of the above exception, another exception occurred:

Traceback (most recent call last):
  File "/home/opc/scripts/OCI-SuperDelete/delete.py", line 367, in <module>
    DeleteAny(config, signer, processCompartments, "ai_anomaly_detection.AnomalyDetectionClient", "data_asset")
  File "/home/opc/scripts/OCI-SuperDelete/ocimodules/AnyDelete.py", line 45, in DeleteAny
    items = eval("oci.pagination.list_call_get_all_results(object.{}, compartment_id=Compartment.id{}, retry_strategy=oci.retry.DEFAULT_RETRY_STRATEGY).data".format(ListCommand, Extra))
  File "<string>", line 1, in <module>
  File "/home/opc/python/lib/python3.7/site-packages/oci/pagination/pagination_utils.py", line 205, in list_call_get_all_results
    for response in list_call_get_all_results_generator(list_func_ref, 'response', *list_func_args, **list_func_kwargs):
  File "/home/opc/python/lib/python3.7/site-packages/oci/pagination/pagination_utils.py", line 274, in list_call_get_all_results_generator
    call_result = retry.DEFAULT_RETRY_STRATEGY.make_retrying_call(list_func_ref, *list_func_args, **list_func_kwargs)
  File "/home/opc/python/lib/python3.7/site-packages/oci/retry/retry.py", line 308, in make_retrying_call
    response = func_ref(*func_args, **func_kwargs)
  File "/home/opc/python/lib/python3.7/site-packages/oci/ai_anomaly_detection/anomaly_detection_client.py", line 2841, in list_data_assets
    required_arguments=required_arguments)
  File "/home/opc/python/lib/python3.7/site-packages/oci/retry/retry.py", line 308, in make_retrying_call
    response = func_ref(*func_args, **func_kwargs)
  File "/home/opc/python/lib/python3.7/site-packages/oci/base_client.py", line 529, in call_api
    response = self.request(request, allow_control_chars, operation_name, api_reference_link)
  File "/home/opc/python/lib/python3.7/site-packages/circuitbreaker.py", line 52, in wrapper
    return self.call(function, *args, **kwargs)
  File "/home/opc/python/lib/python3.7/site-packages/circuitbreaker.py", line 67, in call
    result = func(*args, **kwargs)
  File "/home/opc/python/lib/python3.7/site-packages/oci/base_client.py", line 694, in request
    raise exceptions.RequestException(e)
oci.exceptions.RequestException: (MaxRetryError("OCIConnectionPool(host='anomalydetection.aiservice.us-ashburn-1.oci.oraclecloud.com', port=443): Max retries exceeded with url: /20210101/dataAssets?compartmentId=ocid1.compartment.oc1..aaaaaaaaykn3hgoydak7wfeqplsd7vuqgsf2lhiojtcze4g3ojoowisxqcfq (Caused by NewConnectionError('<oci.base_client.OCIConnection object at 0x7f4734370d68>: Failed to establish a new connection: [Errno -2] Name or service not known'))"), 'Request Endpoint: GET https://anomalydetection.aiservice.us-ashburn-1.oci.oraclecloud.com/20210101/dataAssets See https://docs.oracle.com/en-us/iaas/Content/API/Concepts/sdk_troubleshooting.htm for help troubleshooting this error, or contact support and provide this full error message.')
